2024-03-24 16:21:54,750 ERROR: Exception on /auth/login [GET] [in /home/wmstest/whm/whmenv/lib/python3.10/site-packages/flask/app.py:828]
Traceback (most recent call last):
  File "/home/wmstest/whm/whmenv/lib/python3.10/site-packages/flask/app.py", line 1463, in wsgi_app
    response = self.full_dispatch_request()
  File "/home/wmstest/whm/whmenv/lib/python3.10/site-packages/flask/app.py", line 872, in full_dispatch_request
    rv = self.handle_user_exception(e)
  File "/home/wmstest/whm/whmenv/lib/python3.10/site-packages/flask/app.py", line 870, in full_dispatch_request
    rv = self.dispatch_request()
  File "/home/wmstest/whm/whmenv/lib/python3.10/site-packages/flask/app.py", line 855, in dispatch_request
    return self.ensure_sync(self.view_functions[rule.endpoint])(**view_args)  # type: ignore[no-any-return]
  File "/home/wmstest/whm/app/auth/auth.py", line 29, in login
    return render_template('auth/login.html', form=form)
  File "/home/wmstest/whm/whmenv/lib/python3.10/site-packages/flask/templating.py", line 150, in render_template
    return _render(app, template, context)
  File "/home/wmstest/whm/whmenv/lib/python3.10/site-packages/flask/templating.py", line 131, in _render
    rv = template.render(context)
  File "/home/wmstest/whm/whmenv/lib/python3.10/site-packages/jinja2/environment.py", line 1301, in render
    self.environment.handle_exception()
  File "/home/wmstest/whm/whmenv/lib/python3.10/site-packages/jinja2/environment.py", line 936, in handle_exception
    raise rewrite_traceback_stack(source=source)
  File "/home/wmstest/whm/app/templates/auth/login.html", line 2, in top-level template code
    {% extends "base.html" %}
  File "/home/wmstest/whm/app/templates/base.html", line 25, in top-level template code
    <li><a href="{{ url_for('auth.register') }}">Register</a></li>
  File "/home/wmstest/whm/whmenv/lib/python3.10/site-packages/flask/app.py", line 1074, in url_for
    return self.handle_url_build_error(error, endpoint, values)
  File "/home/wmstest/whm/whmenv/lib/python3.10/site-packages/flask/app.py", line 1063, in url_for
    rv = url_adapter.build(  # type: ignore[union-attr]
  File "/home/wmstest/whm/whmenv/lib/python3.10/site-packages/werkzeug/routing/map.py", line 919, in build
    raise BuildError(endpoint, values, method, self)
werkzeug.routing.exceptions.BuildError: Could not build url for endpoint 'auth.register'. Did you mean 'auth.login' instead?
2024-03-24 16:24:04,452 INFO: MyApp startup [in /home/wmstest/whm/app/__init__.py:37]
2024-03-24 16:24:19,462 ERROR: Exception on /auth/login [POST] [in /home/wmstest/whm/whmenv/lib/python3.10/site-packages/flask/app.py:828]
Traceback (most recent call last):
  File "/home/wmstest/whm/whmenv/lib/python3.10/site-packages/sqlalchemy/engine/base.py", line 1970, in _exec_single_context
    self.dialect.do_execute(
  File "/home/wmstest/whm/whmenv/lib/python3.10/site-packages/sqlalchemy/engine/default.py", line 924, in do_execute
    cursor.execute(statement, parameters)
sqlite3.OperationalError: no such column: user.role_id

The above exception was the direct cause of the following exception:

Traceback (most recent call last):
  File "/home/wmstest/whm/whmenv/lib/python3.10/site-packages/flask/app.py", line 1463, in wsgi_app
    response = self.full_dispatch_request()
  File "/home/wmstest/whm/whmenv/lib/python3.10/site-packages/flask/app.py", line 872, in full_dispatch_request
    rv = self.handle_user_exception(e)
  File "/home/wmstest/whm/whmenv/lib/python3.10/site-packages/flask/app.py", line 870, in full_dispatch_request
    rv = self.dispatch_request()
  File "/home/wmstest/whm/whmenv/lib/python3.10/site-packages/flask/app.py", line 855, in dispatch_request
    return self.ensure_sync(self.view_functions[rule.endpoint])(**view_args)  # type: ignore[no-any-return]
  File "/home/wmstest/whm/app/auth/auth.py", line 18, in login
    user = User.query.filter_by(email=form.email.data).first()
  File "/home/wmstest/whm/whmenv/lib/python3.10/site-packages/sqlalchemy/orm/query.py", line 2728, in first
    return self.limit(1)._iter().first()  # type: ignore
  File "/home/wmstest/whm/whmenv/lib/python3.10/site-packages/sqlalchemy/orm/query.py", line 2827, in _iter
    result: Union[ScalarResult[_T], Result[_T]] = self.session.execute(
  File "/home/wmstest/whm/whmenv/lib/python3.10/site-packages/sqlalchemy/orm/session.py", line 2306, in execute
    return self._execute_internal(
  File "/home/wmstest/whm/whmenv/lib/python3.10/site-packages/sqlalchemy/orm/session.py", line 2191, in _execute_internal
    result: Result[Any] = compile_state_cls.orm_execute_statement(
  File "/home/wmstest/whm/whmenv/lib/python3.10/site-packages/sqlalchemy/orm/context.py", line 293, in orm_execute_statement
    result = conn.execute(
  File "/home/wmstest/whm/whmenv/lib/python3.10/site-packages/sqlalchemy/engine/base.py", line 1421, in execute
    return meth(
  File "/home/wmstest/whm/whmenv/lib/python3.10/site-packages/sqlalchemy/sql/elements.py", line 514, in _execute_on_connection
    return connection._execute_clauseelement(
  File "/home/wmstest/whm/whmenv/lib/python3.10/site-packages/sqlalchemy/engine/base.py", line 1643, in _execute_clauseelement
    ret = self._execute_context(
  File "/home/wmstest/whm/whmenv/lib/python3.10/site-packages/sqlalchemy/engine/base.py", line 1849, in _execute_context
    return self._exec_single_context(
  File "/home/wmstest/whm/whmenv/lib/python3.10/site-packages/sqlalchemy/engine/base.py", line 1989, in _exec_single_context
    self._handle_dbapi_exception(
  File "/home/wmstest/whm/whmenv/lib/python3.10/site-packages/sqlalchemy/engine/base.py", line 2356, in _handle_dbapi_exception
    raise sqlalchemy_exception.with_traceback(exc_info[2]) from e
  File "/home/wmstest/whm/whmenv/lib/python3.10/site-packages/sqlalchemy/engine/base.py", line 1970, in _exec_single_context
    self.dialect.do_execute(
  File "/home/wmstest/whm/whmenv/lib/python3.10/site-packages/sqlalchemy/engine/default.py", line 924, in do_execute
    cursor.execute(statement, parameters)
sqlalchemy.exc.OperationalError: (sqlite3.OperationalError) no such column: user.role_id
[SQL: SELECT user.id AS user_id, user.email AS user_email, user.password AS user_password, user.role_id AS user_role_id, user.must_reset_password AS user_must_reset_password 
FROM user 
WHERE user.email = ?
 LIMIT ? OFFSET ?]
[parameters: ('Dayroock@gmail.com', 1, 0)]
(Background on this error at: https://sqlalche.me/e/20/e3q8)
2024-03-24 16:33:17,791 INFO: MyApp startup [in /home/wmstest/whm/app/__init__.py:37]
2024-03-24 16:35:03,301 INFO: MyApp startup [in /home/wmstest/whm/app/__init__.py:37]
2024-03-24 16:35:15,755 INFO: MyApp startup [in /home/wmstest/whm/app/__init__.py:37]
2024-03-24 16:36:45,293 INFO: MyApp startup [in /home/wmstest/whm/app/__init__.py:37]
2024-03-24 16:39:22,814 INFO: MyApp startup [in /home/wmstest/whm/app/__init__.py:37]
2024-03-24 16:40:59,172 INFO: MyApp startup [in /home/wmstest/whm/app/__init__.py:37]
2024-03-24 16:41:58,782 INFO: MyApp startup [in /home/wmstest/whm/app/__init__.py:37]
2024-03-24 16:42:14,955 INFO: MyApp startup [in /home/wmstest/whm/app/__init__.py:37]
2024-03-24 16:42:20,918 INFO: MyApp startup [in /home/wmstest/whm/app/__init__.py:37]
2024-03-24 16:49:26,473 INFO: MyApp startup [in /home/wmstest/whm/app/__init__.py:37]
2024-03-24 16:50:27,180 INFO: MyApp startup [in /home/wmstest/whm/app/__init__.py:37]
2024-03-24 16:54:05,322 INFO: MyApp startup [in /home/wmstest/whm/app/__init__.py:37]
2024-03-24 16:56:04,327 INFO: MyApp startup [in /home/wmstest/whm/app/__init__.py:37]
2024-03-24 16:56:55,816 INFO: MyApp startup [in /home/wmstest/whm/app/__init__.py:37]
2024-03-24 16:59:28,891 INFO: MyApp startup [in /home/wmstest/whm/app/__init__.py:37]
2024-03-24 16:59:43,089 INFO: MyApp startup [in /home/wmstest/whm/app/__init__.py:37]
