2024-03-24 06:19:16,166 INFO: MyApp startup [in /home/wmstest/whm/app/__init__.py:37]
2024-03-24 06:22:18,769 INFO: MyApp startup [in /home/wmstest/whm/app/__init__.py:37]
2024-03-24 06:23:31,318 INFO: MyApp startup [in /home/wmstest/whm/app/__init__.py:37]
2024-03-24 06:24:41,051 INFO: MyApp startup [in /home/wmstest/whm/app/__init__.py:37]
2024-03-24 06:26:41,910 INFO: MyApp startup [in /home/wmstest/whm/app/__init__.py:37]
2024-03-24 06:29:33,069 INFO: MyApp startup [in /home/wmstest/whm/app/__init__.py:37]
2024-03-24 15:36:29,453 INFO: MyApp startup [in /home/wmstest/whm/app/__init__.py:37]
2024-03-24 15:41:10,939 INFO: MyApp startup [in /home/wmstest/whm/app/__init__.py:37]
2024-03-24 15:42:40,864 INFO: MyApp startup [in /home/wmstest/whm/app/__init__.py:37]
2024-03-24 16:05:50,725 INFO: MyApp startup [in /home/wmstest/whm/app/__init__.py:37]
2024-03-24 16:13:34,904 INFO: MyApp startup [in /home/wmstest/whm/app/__init__.py:37]
2024-03-24 16:14:12,207 INFO: MyApp startup [in /home/wmstest/whm/app/__init__.py:37]
2024-03-24 16:14:15,973 ERROR: Exception on /auth/login [GET] [in /home/wmstest/whm/whmenv/lib/python3.10/site-packages/flask/app.py:828]
Traceback (most recent call last):
  File "/home/wmstest/whm/whmenv/lib/python3.10/site-packages/flask/app.py", line 1463, in wsgi_app
    response = self.full_dispatch_request()
  File "/home/wmstest/whm/whmenv/lib/python3.10/site-packages/flask/app.py", line 872, in full_dispatch_request
    rv = self.handle_user_exception(e)
  File "/home/wmstest/whm/whmenv/lib/python3.10/site-packages/flask/app.py", line 870, in full_dispatch_request
    rv = self.dispatch_request()
  File "/home/wmstest/whm/whmenv/lib/python3.10/site-packages/flask/app.py", line 855, in dispatch_request
    return self.ensure_sync(self.view_functions[rule.endpoint])(**view_args)  # type: ignore[no-any-return]
  File "/home/wmstest/whm/app/auth/auth.py", line 29, in login
    return render_template('auth/login.html', form=form)
  File "/home/wmstest/whm/whmenv/lib/python3.10/site-packages/flask/templating.py", line 149, in render_template
    template = app.jinja_env.get_or_select_template(template_name_or_list)
  File "/home/wmstest/whm/whmenv/lib/python3.10/site-packages/jinja2/environment.py", line 1081, in get_or_select_template
    return self.get_template(template_name_or_list, parent, globals)
  File "/home/wmstest/whm/whmenv/lib/python3.10/site-packages/jinja2/environment.py", line 1010, in get_template
    return self._load_template(name, globals)
  File "/home/wmstest/whm/whmenv/lib/python3.10/site-packages/jinja2/environment.py", line 969, in _load_template
    template = self.loader.load(self, name, self.make_globals(globals))
  File "/home/wmstest/whm/whmenv/lib/python3.10/site-packages/jinja2/loaders.py", line 137, in load
    code = environment.compile(source, name, filename)
  File "/home/wmstest/whm/whmenv/lib/python3.10/site-packages/jinja2/environment.py", line 768, in compile
    self.handle_exception(source=source_hint)
  File "/home/wmstest/whm/whmenv/lib/python3.10/site-packages/jinja2/environment.py", line 936, in handle_exception
    raise rewrite_traceback_stack(source=source)
  File "/home/wmstest/whm/app/templates/auth/login.html", line 17, in template
    {{ form.email(class="form-control" required=true) }}
jinja2.exceptions.TemplateSyntaxError: expected token ',', got 'required'
2024-03-24 16:17:00,225 INFO: MyApp startup [in /home/wmstest/whm/app/__init__.py:37]
2024-03-24 16:17:03,791 ERROR: Exception on /auth/login [GET] [in /home/wmstest/whm/whmenv/lib/python3.10/site-packages/flask/app.py:828]
Traceback (most recent call last):
  File "/home/wmstest/whm/whmenv/lib/python3.10/site-packages/flask/app.py", line 1463, in wsgi_app
    response = self.full_dispatch_request()
  File "/home/wmstest/whm/whmenv/lib/python3.10/site-packages/flask/app.py", line 872, in full_dispatch_request
    rv = self.handle_user_exception(e)
  File "/home/wmstest/whm/whmenv/lib/python3.10/site-packages/flask/app.py", line 870, in full_dispatch_request
    rv = self.dispatch_request()
  File "/home/wmstest/whm/whmenv/lib/python3.10/site-packages/flask/app.py", line 855, in dispatch_request
    return self.ensure_sync(self.view_functions[rule.endpoint])(**view_args)  # type: ignore[no-any-return]
  File "/home/wmstest/whm/app/auth/auth.py", line 29, in login
    return render_template('auth/login.html', form=form)
  File "/home/wmstest/whm/whmenv/lib/python3.10/site-packages/flask/templating.py", line 149, in render_template
    template = app.jinja_env.get_or_select_template(template_name_or_list)
  File "/home/wmstest/whm/whmenv/lib/python3.10/site-packages/jinja2/environment.py", line 1081, in get_or_select_template
    return self.get_template(template_name_or_list, parent, globals)
  File "/home/wmstest/whm/whmenv/lib/python3.10/site-packages/jinja2/environment.py", line 1010, in get_template
    return self._load_template(name, globals)
  File "/home/wmstest/whm/whmenv/lib/python3.10/site-packages/jinja2/environment.py", line 969, in _load_template
    template = self.loader.load(self, name, self.make_globals(globals))
  File "/home/wmstest/whm/whmenv/lib/python3.10/site-packages/jinja2/loaders.py", line 137, in load
    code = environment.compile(source, name, filename)
  File "/home/wmstest/whm/whmenv/lib/python3.10/site-packages/jinja2/environment.py", line 768, in compile
    self.handle_exception(source=source_hint)
  File "/home/wmstest/whm/whmenv/lib/python3.10/site-packages/jinja2/environment.py", line 936, in handle_exception
    raise rewrite_traceback_stack(source=source)
  File "/home/wmstest/whm/app/templates/auth/login.html", line 17, in template
    {{ form.email(class="form-control", required) }} <!-- Corrected here -->
jinja2.exceptions.TemplateSyntaxError: invalid syntax for function call expression
2024-03-24 16:20:41,910 INFO: MyApp startup [in /home/wmstest/whm/app/__init__.py:37]
2024-03-24 16:20:44,922 ERROR: Exception on /auth/login [GET] [in /home/wmstest/whm/whmenv/lib/python3.10/site-packages/flask/app.py:828]
Traceback (most recent call last):
  File "/home/wmstest/whm/whmenv/lib/python3.10/site-packages/flask/app.py", line 1463, in wsgi_app
    response = self.full_dispatch_request()
  File "/home/wmstest/whm/whmenv/lib/python3.10/site-packages/flask/app.py", line 872, in full_dispatch_request
    rv = self.handle_user_exception(e)
  File "/home/wmstest/whm/whmenv/lib/python3.10/site-packages/flask/app.py", line 870, in full_dispatch_request
    rv = self.dispatch_request()
  File "/home/wmstest/whm/whmenv/lib/python3.10/site-packages/flask/app.py", line 855, in dispatch_request
    return self.ensure_sync(self.view_functions[rule.endpoint])(**view_args)  # type: ignore[no-any-return]
  File "/home/wmstest/whm/app/auth/auth.py", line 29, in login
    return render_template('auth/login.html', form=form)
  File "/home/wmstest/whm/whmenv/lib/python3.10/site-packages/flask/templating.py", line 150, in render_template
    return _render(app, template, context)
  File "/home/wmstest/whm/whmenv/lib/python3.10/site-packages/flask/templating.py", line 131, in _render
    rv = template.render(context)
  File "/home/wmstest/whm/whmenv/lib/python3.10/site-packages/jinja2/environment.py", line 1301, in render
    self.environment.handle_exception()
  File "/home/wmstest/whm/whmenv/lib/python3.10/site-packages/jinja2/environment.py", line 936, in handle_exception
    raise rewrite_traceback_stack(source=source)
  File "/home/wmstest/whm/app/templates/auth/login.html", line 2, in top-level template code
    {% extends "base.html" %}
  File "/home/wmstest/whm/app/templates/base.html", line 20, in top-level template code
    <li><a href="{{ url_for('main.inventory_dashboard') }}">Inventory</a></li>
  File "/home/wmstest/whm/whmenv/lib/python3.10/site-packages/flask/app.py", line 1074, in url_for
    return self.handle_url_build_error(error, endpoint, values)
  File "/home/wmstest/whm/whmenv/lib/python3.10/site-packages/flask/app.py", line 1063, in url_for
    rv = url_adapter.build(  # type: ignore[union-attr]
  File "/home/wmstest/whm/whmenv/lib/python3.10/site-packages/werkzeug/routing/map.py", line 919, in build
    raise BuildError(endpoint, values, method, self)
werkzeug.routing.exceptions.BuildError: Could not build url for endpoint 'main.inventory_dashboard'. Did you mean 'inventory.inventory_dashboard' instead?
2024-03-24 16:21:51,990 INFO: MyApp startup [in /home/wmstest/whm/app/__init__.py:37]
